Workbook

Sheet TOUTAB2
A1: Table 2 : Visitor Arrivals by Usual Country of Residence
D3: Australia | E3: New | F3: New | G3: Other | H3: Europe | I3: North | J3: Japan | K3: Other | L3: Not | M3: TOTAL
B4: Year / Quarter | E4: Zealand | F4: Caledonia | G4: Pacific | I4: America | K4: Countries | L4: Stated
G6: Countries
B7: YEAR
B8: 1993 | D8: 23258 | E8: 6133 | F8: 5692 | G8: 3064 | H8: 2190 | I8: 1351 | J8: 1174 | K8: 937 | L8: 679 | M8: 44478
B9: 1994 | D9: 22942 | E9: 5293 | F9: 5464 | G9: 2558 | H9: 2295 | I9: 1140 | J9: 1227 | K9: 843 | L9: 378 | M9: 42140
B10: 1995 | D10: =SUM(D14:D17) -> 24401 | E10: =SUM(E14:E17) -> 6436 | F10: 4971 | G10: =SUM(G14:G17) -> 2417 | H10: =SUM(H14:H17) -> 2352 | I10: =SUM(I14:I17) -> 1157 | J10: =SUM(J14:J17) -> 981 | K10: =SUM(K14:K17) -> 967 | L10: =SUM(L14:L17) -> 39 | M10: =SUM(M14:M17) -> 43721
B11: 1996 | D11: =SUM(D22:D25) -> 26690 | E11: =SUM(E22:E25) -> 5689 | F11: 5409 | G11: =SUM(G22:G25) -> 2600 | H11: =SUM(H22:H25) -> 2644 | I11: =SUM(I22:I25) -> 1223 | J11: =SUM(J22:J25) -> 927 | K11: =SUM(K22:K25) -> 884 | L11: =SUM(L22:L25) -> 57 | M11: =SUM(M22:M25) -> 46123
B12: 1997 | D12: =SUM(D26:D29) -> 28976 | E12: =SUM(E26:E29) -> 6108 | F12: =SUM(F26:F29) -> 5431 | G12: =SUM(G26:G29) -> 2998 | H12: =SUM(H26:H29) -> 2894 | I12: =SUM(I26:I29) -> 1172 | J12: =SUM(J26:J29) -> 948 | K12: =SUM(K26:K29) -> 999 | ... M12: =SUM(M26:M29) -> 49624
B13: 1998 | D13: =+D30+D31+D32+D33 -> 32498 | E13: =+E30+E31+E32+E33 -> 6180 | F13: =+F30+F31+F32+F33 -> 5824 | G13: =+G30+G31+G32+G33 -> 2080 | H13: =+H30+H31+H32+H33 -> 2337 | I13: =+I30+I31+I32+I33 -> 1297 | J13: =+J30+J31+J32+J33 -> 965 | K13: =+K30+K31+K32+K33 -> 871 | ... M13: =+M30+M31+M32+M33 -> 52085
B14: 1995 | C14: 1st | D14: 4644 | E14: 883 | F14: 1141 | G14: 397 | H14: 411 | I14: 201 | J14: 271 | K14: 148 | L14: 9 | M14: 8105
C15: 2nd | D15: 6499 | E15: 1735 | F15: 1065 | G15: 681 | H15: 455 | I15: 302 | J15: 195 | K15: 258 | L15: 15 | M15: 11205
C16: 3rd | D16: 6680 | E16: 2362 | F16: 1255 | G16: 785 | H16: 854 | I16: 392 | J16: 298 | K16: 277 | L16: 8 | M16: 12911
C17: 4th | D17: 6578 | E17: 1456 | F17: 1510 | G17: 554 | H17: 632 | I17: 262 | J17: 217 | K17: 284 | L17: 7 | M17: 11500
B18: 1999 | D18: =SUM(D34:D37) -> 30769 | E18: =SUM(E34:E37) -> 6487 | F18: =SUM(F34:F37) -> 5037 | G18: =SUM(G34:G37) -> 2317 | H18: =SUM(H34:H37) -> 3063 | I18: =SUM(I34:I37) -> 1343 | J18: =SUM(J34:J37) -> 915 | K18: =SUM(K34:K37) -> 764 | ... M18: =SUM(M34:M37) -> 50746
B19: 2000 | D19: =SUM(D38:D41) -> 36805 | E19: =SUM(E38:E41) -> 8024 | F19: =SUM(F38:F41) -> 4124 | G19: =SUM(G38:G41) -> 2039 | H19: =SUM(H38:H41) -> 3401 | I19: =SUM(I38:I41) -> 1547 | J19: =SUM(J38:J41) -> 811 | K19: =SUM(K38:K41) -> 831 | ... M19: =SUM(M38:M41) -> 57591
B20: 2001 | D20: =SUM(D42:D45) -> 41016 | E20: =SUM(E42:E45) -> 7512 | F20: =SUM(F42:F45) -> 4039 | G20: =SUM(G42:G45) -> 2182 | H20: =SUM(H42:H45) -> 2683 | I20: =SUM(I42:I45) -> 1413 | J20: =SUM(J42:J45) -> 834 | K20: =SUM(K42:K45) -> 936 | ... M20: =SUM(M42:M45) -> 53300
B22: 1996 | C22: 1st | D22: 5417 | E22: 962 | F22: 1087 | G22: 404 | H22: 478 | I22: 194 | J22: 206 | K22: 178 | L22: 2 | M22: 8928
C23: 2nd | D23: 7261 | E23: 1593 | F23: 1401 | G23: 648 | H23: 458 | I23: 306 | J23: 157 | K23: 172 | L23: 2 | M23: 11998
C24: 3rd | D24: 6872 | E24: 2058 | F24: 1641 | G24: 814 | H24: 1002 | I24: 449 | J24: 343 | K24: 264 | L24: 10 | M24: 13453
C25: 4th | D25: 7140 | E25: 1076 | F25: 1280 | G25: 734 | H25: 706 | I25: 274 | J25: 221 | K25: 270 | L25: 43 | M25: 11744
B26: 1997 | C26: 1st | D26: 5952 | E26: 780 | F26: 1283 | G26: 813 | H26: 599 | I26: 217 | J26: 189 | K26: 231 | L26: 37 | M26: =+D26+E26+F26+G26+H26+I26+J26+K26+L26 -> 10101
C27: 2nd | D27: 7729 | E27: 1855 | F27: 1150 | G27: 626 | H27: 524 | I27: 239 | J27: 221 | K27: 249 | L27: 25 | M27: 12618
C28: 3rd | D28: 7536 | E28: 2288 | F28: 1409 | G28: 954 | H28: 994 | I28: 452 | J28: 336 | K28: 269 | L28: 13 | M28: 14251
C29: 4th | D29: 7759 | E29: 1185 | F29: 1589 | G29: 605 | H29: 777 | I29: 264 | J29: 202 | K29: 250 | L29: 23 | M29: 12654
B30: 1998 | C30: 1st | D30: 5938 | E30: 737 | F30: 908 | G30: 307 | H30: 463 | I30: 213 | J30: 167 | K30: 314 | L30: 24 | M30: 9071
C31: 2nd | D31: 8226 | E31: 1785 | F31: 1547 | G31: 553 | H31: 633 | I31: 358 | J31: 298 | K31: 172 | L31: 2 | M31: 13574
C32: 3rd | D32: =+D80+D81+D82 -> 9419 | E32: =+E80+E81+E82 -> 2302 | F32: =+F80+F81+F82 -> 2014 | G32: =+G80+G81+G82 -> 696 | H32: =+H80+H81+H82 -> 766 | I32: =+I80+I81+I82 -> 433 | J32: =+J80+J81+J82 -> 362 | K32: =+K80+K81+K82 -> 217 | ... M32: =+M80+M81+M82 -> 16212
C33: 4th | D33: =+D83+D84+D85 -> 8915 | E33: =+E83+E84+E85 -> 1356 | F33: =+F83+F84+F85 -> 1355 | G33: =+G83+G84+G85 -> 524 | H33: =+H83+H84+H85 -> 475 | I33: =+I83+I84+I85 -> 293 | J33: =+J83+J84+J85 -> 138 | K33: =+K83+K84+K85 -> 168 | ... M33: =+M83+M84+M85 -> 13228
B34: 1999 | C34: 1st | D34: =SUM(D86:D88) -> 6287 | E34: =SUM(E86:E88) -> 927 | F34: =SUM(F86:F88) -> 1260 | G34: =SUM(G86:G88) -> 372 | H34: =SUM(H86:H88) -> 579 | I34: =SUM(I86:I88) -> 236 | J34: =SUM(J86:J88) -> 188 | K34: =SUM(K86:K88) -> 200 | L34: - | M34: =SUM(M86:M88) -> 10049
C35: 2nd | D35: =SUM(D89:D91) -> 6889 | E35: =SUM(E89:E91) -> 1456 | F35: =SUM(F89:F91) -> 1173 | G35: =SUM(G89:G91) -> 550 | H35: =SUM(H89:H91) -> 656 | I35: =SUM(I89:I91) -> 375 | J35: =SUM(J89:J91) -> 276 | K35: =SUM(K89:K91) -> 199 | L35: - | M35: =SUM(M89:M91) -> 11574
C36: 3rd | D36: =SUM(D92:D94) -> 9428 | E36: =SUM(E92:E94) -> 2673 | F36: =SUM(F92:F94) -> 1086 | G36: =SUM(G92:G94) -> 781 | H36: =SUM(H92:H94) -> 1015 | I36: =SUM(I92:I94) -> 462 | J36: =SUM(J92:J94) -> 247 | K36: =SUM(K92:K94) -> 215 | ... M36: =SUM(M92:M94) -> 15931
C37: 4th | D37: =SUM(D95:D97) -> 8165 | E37: =SUM(E95:E97) -> 1431 | F37: =SUM(F95:F97) -> 1518 | G37: =SUM(G95:G97) -> 614 | H37: =SUM(H95:H97) -> 813 | I37: =SUM(I95:I97) -> 270 | J37: =SUM(J95:J97) -> 204 | K37: =SUM(K95:K97) -> 150 | ... M37: =SUM(M95:M97) -> 13192
B38: 2000 | C38: 1st | D38: =SUM(D98:D100) -> 7808 | E38: =SUM(E98:E100) -> 1031 | F38: =SUM(F98:F100) -> 820 | G38: =SUM(G98:G100) -> 377 | H38: =SUM(H98:H100) -> 696 | I38: =SUM(I98:I100) -> 249 | J38: =SUM(J98:J100) -> 199 | K38: =SUM(K98:K100) -> 183 | ... M38: =SUM(M98:M100) -> 11365
C39: 2nd | D39: =SUM(D101:D103) -> 9749 | E39: =SUM(E101:E103) -> 2394 | F39: =SUM(F101:F103) -> 923 | G39: =SUM(G101:G103) -> 580 | H39: =SUM(H101:H103) -> 771 | I39: =SUM(I101:I103) -> 369 | J39: =SUM(J101:J103) -> 156 | K39: =SUM(K101:K103) -> 191 | ... M39: =SUM(M101:M103) -> 15138
C40: 3rd | D40: =SUM(D104:D106) -> 9801 | E40: =SUM(E104:E106) -> 2711 | F40: =SUM(F104:F106) -> 1046 | G40: =SUM(G104:G106) -> 444 | H40: =SUM(H104:H106) -> 1132 | I40: =SUM(I104:I106) -> 563 | J40: =SUM(J104:J106) -> 248 | K40: =SUM(K104:K106) -> 235 | L40: - | M40: =SUM(M104:M106) -> 16180
C41: 4th | D41: =SUM(D107:D109) -> 9447 | E41: =SUM(E107:E109) -> 1888 | F41: =SUM(F107:F109) -> 1335 | G41: =SUM(G107:G109) -> 638 | H41: =SUM(H107:H109) -> 802 | I41: =SUM(I107:I109) -> 366 | J41: =SUM(J107:J109) -> 208 | K41: =SUM(K107:K109) -> 222 | ... M41: =SUM(M107:M109) -> 14908
B42: 2001 | C42: 1st | D42: =SUM(D64:D67) -> 10158 | E42: =SUM(E110:E112) -> 1187 | F42: =SUM(F110:F112) -> 815 | G42: =SUM(G110:G112) -> 465 | H42: =SUM(H110:H112) -> 601 | I42: =SUM(I110:I112) -> 257 | J42: =SUM(J110:J112) -> 206 | K42: =SUM(K110:K112) -> 221 | L42: =SUM(L110:L112) -> 13 | ... N42: =SUM(N110:N112) -> 0
C43: 2nd | D43: =SUM(D65:D68) -> 10022 | E43: =SUM(E113:E115) -> 2039 | F43: =SUM(F113:F115) -> 786 | G43: =SUM(G113:G115) -> 452 | H43: =SUM(H113:H115) -> 562 | I43: =SUM(I113:I115) -> 344 | J43: =SUM(J113:J115) -> 203 | K43: =SUM(K113:K115) -> 173 | L43: =SUM(L113:L115) -> 9 | M43: =SUM(M113:M115) -> 12636
...

Sheet Table 1 Summary
B1: Table 1 : Summary of Overseas Migration
B2: Tableau 1 : Résumé des échanges migratoires avec l'extérieur
D4: ARRIVALS / ARRIVEES | P4: DEPARTURES / DEPARTURES | Z4: Arrivals | AB4: Cruiseship
D5: PORT VILA | H5: LUGANVILLE | L5: TOTAL | P5: PORT VILA | T5: LUGANVILLE | V5: TOTAL | AB5: Arrivals/ | AD5: Total Visitors
B6: Year | C6: Month | D6: Residents | F6: Visitors | H6: Residents | J6: Visitors | L6: Residents | N6: Visitors | P6: Resident | R6: Visitor | T6: Resident | U6: Visitors | V6: Resident | X6: Visitors | Z6: Yacht | AB6: Croisièristes | AF6: Année | AG6: Mois
D7: Résidents | F7: Visiteurs | H7: Résidents | J7: Visiteurs | L7: Résidents | N7: Visiteurs | P7: Résidents | R7: Visiteurs | T7: Résidents | U7: Visiteurs | V7: Résidents | X7: Visiteurs | Z7: Voilier
B8: 2005 | D8: =SUM(D30:D41) -> 13788 | F8: =SUM(F30:F41) -> 62082 | H8: - | I8: =SUM(I30:I41) -> 0 | J8: - | K8: =SUM(K30:K41) -> 0 | L8: =SUM(L30:L41) -> 13788 | M8: =SUM(M30:M41) -> 0 | N8: =SUM(N30:N41) -> 62082 | P8: =SUM(P30:P41) -> 13608 | Q8: =SUM(Q30:Q41) -> 0 | R8: =SUM(R30:R41) -> 62364 | S8: =SUM(S30:S41) -> 0 | T8: - | U8: - | V8: =SUM(V30:V41) -> 13608 | W8: =SUM(W30:W41) -> 0 | X8: =SUM(X30:X41) -> 62364 | Z8: - | AB8: =SUM(AB30:AB41) -> 63554 | AF8: 2005 | AH8: Revised on 10/12/13
B9: 2006 | D9: =SUM(D42:D53) -> 14841 | F9: =SUM(F42:F53) -> 67787 | H9: =SUM(H42:H53) -> 85 | I9: =SUM(I42:I53) -> 0 | J9: =SUM(J42:J53) -> 392 | K9: =SUM(K42:K53) -> 0 | L9: =SUM(L42:L53) -> 14926 | M9: =SUM(M42:M53) -> 0 | N9: =SUM(N42:N53) -> 68179 | O9: =SUM(O42:O53) -> 83105 | ... S9: =SUM(S42:S53) -> 0 | T9: - | U9: - | V9: =SUM(V42:V53) -> 11557 | W9: =SUM(W42:W53) -> 0 | X9: =SUM(X42:X53) -> 55835 | Y9: =SUM(Y42:Y53) -> 0 | Z9: - | AB9: =SUM(AB42:AB53) -> 85922 | AF9: 2006 | AH9: Revised on 10/12/13
B10: 2007 | D10: =SUM(D54:D65) -> 15186 | F10: =SUM(F54:F65) -> 80054 | H10: =SUM(H54:H65) -> 573 | I10: =SUM(I54:I65) -> 0 | J10: =SUM(J54:J65) -> 1291 | K10: =SUM(K54:K65) -> 0 | L10: =SUM(L54:L65) -> 15759 | M10: =SUM(M54:M65) -> 0 | N10: =SUM(N54:N65) -> 81345 | O10: =SUM(O54:O65) -> 87518 | ... Y10: =SUM(Y54:Y65) -> 0 | Z10: - | AB10: =SUM(AB54:AB65) -> 85737 | AF10: 2007 | AH10: Revised on 10/12/13(still pending revisions to dept. figures)
B11: 2008 | D11: =SUM(D66:D77) -> 18547 | F11: =SUM(F66:F77) -> 88241 | H11: =SUM(H66:H77) -> 585 | J11: =SUM(J66:J77) -> 2416 | L11: =SUM(L66:L77) -> 19132 | N11: =SUM(N66:N77) -> 90657 | P11: =SUM(P66:P77) -> 15847 | R11: =SUM(R66:R77) -> 92429 | T11: =SUM(T66:T77) -> 552 | U11: =SUM(U66:U77) -> 1960 | V11: =SUM(V66:V77) -> 16765 | X11: =SUM(X66:X77) -> 94389 | Z11: - | AB11: =SUM(AB66:AB77) -> 106138 | AD11: =AB11+N11 -> 196795 | AF11: 2008
B12: 2009 | D12: =SUM(D78:D89) -> 19088 | F12: =SUM(F78:F89) -> 97824 | H12: =SUM(H78:H89) -> 594 | I12: =SUM(I78:I89) -> 0 | J12: =SUM(J78:J89) -> 2851 | K12: =SUM(K78:K89) -> 0 | L12: =SUM(L78:L89) -> 19682 | M12: =SUM(M78:M89) -> 0 | N12: =SUM(N78:N89) -> 100675 | O12: =SUM(O78:O89) -> 0 | ... Y12: =SUM(Y78:Y89) -> 0 | Z12: - | AB12: =SUM(AB78:AB89) -> 124818 | AD12: =AB12+N12 -> 225493 | AF12: 2009
B13: 2010 | D13: =SUM(D90:D101) -> 20531 | F13: =SUM(F90:F101) -> 94909 | H13: =SUM(H90:H101) -> 522 | J13: =SUM(J90:J101) -> 2271 | L13: =SUM(L90:L101) -> 21053 | N13: =SUM(N90:N101) -> 97180 | P13: =SUM(P90:P101) -> 13133 | R13: =SUM(R90:R101) -> 104573 | T13: =SUM(T90:T101) -> 188 | U13: =SUM(U90:U101) -> 1999 | V13: =SUM(V90:V101) -> 13321 | X13: =SUM(X90:X101) -> 106572 | Z13: - | AB13: =SUM(AB90:AB101) -> 140468 | AD13: =AB13+N13 -> 237648 | AF13: 2010
B14: 2011 | D14: =SUM(D102:D113) -> 21752 | F14: =SUM(F102:F113) -> 91107 | H14: =SUM(H102:H113) -> 521 | J14: =SUM(J102:J113) -> 2853 | L14: =SUM(L102:L113) -> 22273 | N14: =SUM(N102:N113) -> 93960 | P14: =SUM(P102:P113) -> 12958 | R14: =SUM(R102:R113) -> 96836 | T14: =SUM(T102:T113) -> 156 | U14: =SUM(U102:U113) -> 1954 | V14: =SUM(V102:V113) -> 13114 | X14: =SUM(X102:X113) -> 98790 | Z14: - | AB14: =SUM(AB102:AB113) -> 154938 | AD14: =AB14+N14 -> 248898 | AF14: 2011
B15: 2012 | D15: =SUM(D114:D125) -> 22594 | F15: =SUM(F114:F125) -> 105611 | H15: =SUM(H114:H125) -> 364 | J15: =SUM(J114:J125) -> 2550 | L15: =D15+H15 -> 22958 | N15: =J15+F15 -> 108161 | P15: =SUM(P114:P125) -> 14803 | R15: =SUM(R114:R125) -> 113158 | T15: =SUM(T114:T125) -> 134 | U15: =SUM(U114:U125) -> 2339 | V15: =P15+T15 -> 14937 | X15: =R15+U15 -> 115497 | Z15: - | AB15: =SUM(AB114:AB125) -> 213243 | AD15: =AB15+N15 -> 321404 | AF15: 2012
B16: 2013 | D16: =SUM(D126:D137) -> 25116 | F16: =SUM(F126:F137) -> 106466 | H16: =SUM(H126:H137) -> 495 | J16: =SUM(J126:J137) -> 3643 | L16: =D16+H16 -> 25611 | N16: =J16+F16 -> 110109 | P16: =SUM(P126:P137) -> 16380 | R16: =SUM(R126:R137) -> 118753 | T16: =SUM(T126:T137) -> 164 | U16: =SUM(U126:U137) -> 3496 | V16: =P16+T16 -> 16544 | W16: =SUM(W126:W137) -> 0 | X16: =R16+U16 -> 122249 | Z16: - | AB16: =SUM(AB126:AB137) -> 247296 | AD16: =AB16+N16 -> 357405 | AF16: 2013
B17: 2014 | D17: =SUM(D138:D149) -> 25268 | F17: =SUM(F138:F149) -> 104471 | H17: =SUM(H138:H149) -> 616 | J17: =SUM(J138:J149) -> 4337 | K17: =SUM(K138:K149) -> 0 | L17: =D17+H17 -> 25884 | N17: =J17+F17 -> 108808 | P17: =SUM(P138:P149) -> 18705 | Q17: =SUM(Q138:Q149) -> 0 | R17: =SUM(R138:R149) -> 117236 | T17: =SUM(T138:T149) -> 375 | U17: =SUM(U138:U149) -> 3531 | V17: =P17+T17 -> 19080 | W17: =SUM(W138:W149) -> 0 | X17: =R17+U17 -> 120767 | Z17: - | AB17: =SUM(AB138:AB149) -> 220205 | AD17: =AB17+N17 -> 329013 | AF17: 2014
B18: 2015 | D18: =SUM(D150:D161) -> 26655 | F18: =SUM(F150:F161) -> 85527 | H18: =SUM(H150:H161) -> 307 | J18: =SUM(J150:J161) -> 4425 | K18: =SUM(K150:K161) -> 0 | L18: =D18+H18 -> 26962 | N18: =J18+F18 -> 89952 | O18: =SUM(O150:O161) -> 0 | P18: =SUM(P150:P161) -> 19116 | Q18: =SUM(Q150:Q161) -> 0 | R18: =SUM(R150:R161) -> 95301 | S18: =SUM(S150:S161) -> 0 | T18: =SUM(T150:T161) -> 161 | U18: =SUM(U150:U161) -> 3030 | V18: =P18+T18 -> 19277 | W18: =SUM(W150:W161) -> 0 | X18: =R18+U18 -> 98331 | Y18: =SUM(Y150:Y161) -> 0 | Z18: - | AB18: =SUM(AB150:AB161) -> 201873 | AD18: =AB18+N18 -> 291825 | AF18: 2015
B19: 2016 | D19: =SUM(D162:D173) -> 24801 | F19: =SUM(F162:F173) -> 89358 | H19: =SUM(H162:H173) -> 359 | J19: =SUM(J162:J173) -> 5759 | K19: =SUM(K162:K173) -> 0 | L19: =D19+H19 -> 25160 | N19: =J19+F19 -> 95117 | P19: 20118 | Q19: =SUM(Q162:Q173) -> 0 | R19: 91064 | S19: =SUM(S162:S173) -> 0 | T19: 165 | U19: 4406 | V19: =P19+T19 -> 20283 | W19: =SUM(W162:W173) -> 0 | X19: =R19+U19 -> 95470 | Z19: - | AB19: =SUM(AB162:AB173) -> 256482 | AD19: =N19+AB19 -> 351599 | AF19: 2016
B20: 2017 | D20: =SUM(D174:D185) -> 27418 | F20: =SUM(F174:F185) -> 103463 | H20: =SUM(H174:H185) -> 830 | J20: =SUM(J174:J185) -> 5707 | K20: =SUM(K174:K185) -> 0 | L20: =SUM(L174:L185) -> 28248 | N20: =SUM(N174:N185) -> 109170 | P20: =SUM(P174:P185) -> 25845 | Q20: =SUM(Q174:Q185) -> 0 | R20: =SUM(R174:R185) -> 108427 | S20: =SUM(S174:S185) -> 0 | T20: =SUM(T174:T185) -> 441 | U20: =SUM(U174:U185) -> 3831 | V20: =SUM(V174:V185) -> 26286 | W20: =SUM(W174:W185) -> 0 | ... Y20: =SUM(Y174:Y185) -> 0 | Z20: - | AB20: =SUM(AB174:AB185) -> 223551 | AD20: =SUM(AD174:AD185) -> 332721 | AF20: 2017
B21: 2018 | D21: =SUM(D186:D197) -> 28426 | F21: =SUM(F186:F197) -> 111296 | H21: =SUM(H186:H197) -> 510 | J21: =SUM(J186:J197) -> 4338 | K21: =SUM(K186:K197) -> 0 | L21: =SUM(L186:L197) -> 28936 | N21: =SUM(N186:N197) -> 115634 | P21: =SUM(P186:P197) -> 28160 | R21: =SUM(R186:R197) -> 120736 | T21: =SUM(T186:T197) -> 231 | U21: =SUM(U186:U197) -> 3840 | V21: =SUM(V186:V197) -> 28391 | X21: =SUM(X186:X197) -> 124576 | Y21: =SUM(Y186:Y197) -> 0 | Z21: - | AB21: =SUM(AB186:AB197) -> 234567 | AD21: =SUM(AD186:AD197) -> 350201 | AF21: 2018
B22: 2019 | D22: =SUM(D198:D209) -> 34575 | E22: =SUM(E198:E209) -> 0 | F22: =SUM(F198:F209) -> 117154 | H22: =SUM(H198:H209) -> 326 | I22: =SUM(I198:I209) -> 0 | J22: =SUM(J198:J209) -> 3474 | K22: =SUM(K198:K209) -> 0 | L22: =SUM(L198:L209) -> 34901 | M22: =SUM(M198:M209) -> 0 | N22: =SUM(N198:N209) -> 120628 | O22: =SUM(O198:O209) -> 0 | ... Y22: =SUM(Y198:Y209) -> 0 | Z22: - | AB22: =SUM(AB198:AB209) -> 135357 | AD22: =SUM(AD198:AD209) -> 255985 | AF22: 2019
B23: 2020 | D23: =SUM(D210:D221) -> 10392 | E23: =SUM(E210:E221) -> 0 | F23: =SUM(F210:F221) -> 21764 | H23: =SUM(H210:H221) -> 17 | I23: =SUM(I210:I221) -> 0 | J23: =SUM(J210:J221) -> 201 | K23: =SUM(K210:K221) -> 0 | L23: =SUM(L210:L221) -> 10409 | M23: =SUM(M210:M221) -> 0 | N23: =SUM(N210:N221) -> 21965 | O23: =SUM(O210:O221) -> 0 | ... Y23: =SUM(Y210:Y221) -> 0 | Z23: - | AB23: =SUM(AB210:AB221) -> 60401 | AD23: =SUM(AD210:AD221) -> 82366 | AF23: 2020
B24: 2021 | D24: =SUM(D222:D233) -> 3495 | E24: =SUM(E222:E233) -> 0 | F24: =SUM(F222:F233) -> 0 | H24: =SUM(H222:H233) -> 0 | I24: =SUM(I222:I233) -> 0 | J24: =SUM(J222:J233) -> 0 | K24: =SUM(K222:K233) -> 0 | L24: =SUM(L222:L233) -> 3495 | N24: =SUM(N222:N233) -> 0 | P24: =SUM(P222:P233) -> 8964 | Q24: =SUM(Q222:Q233) -> 0 | R24: =SUM(R222:R233) -> 0 | S24: =SUM(S222:S233) -> 0 | T24: - | U24: - | V24: =SUM(V222:V233) -> 8964 | X24: =SUM(X222:X233) -> 0 | Y24: =SUM(Y222:Y233) -> 0 | Z24: - | AB24: =SUM(AB222:AB233) -> 0 | AD24: =SUM(AD222:AD233) -> 0 | AF24: 2021
B25: 2022 | D25: =SUM(D234:D245) -> 18547 | E25: =SUM(E234:E245) -> 0 | F25: =SUM(F234:F245) -> 30374 | H25: =SUM(H234:H245) -> 0 | I25: =SUM(I234:I245) -> 0 | J25: =SUM(J234:J245) -> 0 | K25: =SUM(K234:K245) -> 0 | L25: =SUM(L234:L245) -> 18547 | M25: =SUM(M234:M245) -> 0 | N25: =SUM(N234:N245) -> 30374 | O25: =SUM(O234:O245) -> 0 | ... S25: =SUM(S234:S245) -> 0 | T25: - | U25: =SUM(U234:U245) -> 12 | V25: =SUM(V234:V245) -> 18172 | W25: =SUM(W234:W245) -> 0 | X25: =SUM(X234:X245) -> 27637 | Y25: =SUM(Y234:Y245) -> 0 | Z25: - | AB25: =SUM(AB234:AB245) -> 34554 | AD25: =SUM(AD234:AD245) -> 65086 | AF25: 2022
B26: 2023 | D26: =SUM(D246:D257) -> 29087 | E26: =SUM(E246:E257) -> 0 | F26: =SUM(F246:F257) -> 75302 | H26: =SUM(H246:H257) -> 350 | I26: =SUM(I246:I257) -> 0 | J26: =SUM(J246:J257) -> 1697 | K26: =SUM(K246:K257) -> 0 | L26: =SUM(L246:L257) -> 29437 | M26: =SUM(M246:M257) -> 0 | N26: =SUM(N246:N257) -> 76999 | O26: =SUM(O246:O257) -> 0 | ... Y26: =SUM(Y246:Y257) -> 0 | Z26: - | AB26: =SUM(AB246:AB257) -> 263578 | AD26: =SUM(AD246:AD257) -> 341605 | AF26: 2023
B27: 2024 | D27: =SUM(D258:D269) -> 29385 | E27: =SUM(E258:E269) -> 0 | F27: =SUM(F258:F269) -> 56685 | H27: =SUM(H258:H269) -> 539 | I27: =SUM(I258:I269) -> 0 | J27: =SUM(J258:J269) -> 2393 | K27: =SUM(K258:K269) -> 0 | L27: =SUM(L258:L269) -> 29924 | M27: =SUM(M258:M269) -> 0 | N27: =SUM(N258:N269) -> 59078 | O27: =SUM(O258:O269) -> 0 | ... Z27: =SUM(Z258:Z269) -> 419 | AB27: =SUM(AB258:AB269) -> 204798 | AD27: =SUM(AD258:AD269) -> 264295 | AF27: 2024
B28: 2025 | D28: =SUM(D270:D281) -> 36822 | E28: =SUM(E270:E281) -> 0 | F28: =SUM(F270:F281) -> 95318 | H28: =SUM(H270:H281) -> 164 | I28: =SUM(I270:I281) -> 0 | J28: =SUM(J270:J281) -> 601 | K28: =SUM(K270:K281) -> 0 | L28: =SUM(L270:L281) -> 36986 | M28: =SUM(M270:M281) -> 0 | N28: =SUM(N270:N281) -> 95919 | O28: =SUM(O270:O281) -> 0 | ... AD28: =SUM(AD270:AD281) -> 275962 | AF28: 2025
B30: 2005 | C30: Jan | D30: 1505 | F30: 4994 | H30: - | J30: - | L30: =D30 -> 1505 | N30: =F30 -> 4994 | O30: =L30+N30 -> 6499 | P30: 1403 | R30: 7103 | T30: - | U30: - | V30: =P30 -> 1403 | X30: =R30 -> 7103 | Z30: - | AB30: 7585 | AF30: 2005 | AG30: Jan
B31: 2005 | C31: Feb | D31: 903 | F31: 3440 | H31: - | J31: - | L31: =D31 -> 903 | N31: =F31 -> 3440 | O31: =L31+N31 -> 4343 | P31: 1120 | R31: 3367 | T31: - | U31: - | V31: =P31 -> 1120 | X31: =R31 -> 3367 | Z31: - | AB31: 3533 | AF31: 2005 | AG31: Fév
B32: 2005 | C32: Mar | D32: 1058 | F32: 4214 | H32: - | J32: - | L32: =D32 -> 1058 | N32: =F32 -> 4214 | O32: =L32+N32 -> 5272 | P32: 1103 | R32: 4014 | T32: - | U32: - | V32: =P32 -> 1103 | X32: =R32 -> 4014 | Z32: - | AB32: 8336 | AF32: 2005 | AG32: Mar
B33: 2005 | C33: Apr | D33: 1186 | F33: 4186 | H33: - | J33: - | L33: =D33 -> 1186 | N33: =F33 -> 4186 | O33: =L33+N33 -> 5372 | P33: 947 | R33: 4244 | T33: - | U33: - | V33: =P33 -> 947 | X33: =R33 -> 4244 | Z33: - | AB33: 7949 | AF33: 2005 | AG33: Avr
B34: 2005 | C34: May | D34: 860 | F34: 4008 | H34: - | J34: - | L34: =D34 -> 860 | N34: =F34 -> 4008 | O34: =L34+N34 -> 4868 | P34: 979 | R34: 4391 | T34: - | U34: - | V34: =P34 -> 979 | X34: =R34 -> 4391 | Z34: - | AB34: 3562 | AF34: 2005 | AG34: Mai
B35: 2005 | C35: Jun | D35: 1111 | F35: 5115 | H35: - | J35: - | L35: =D35 -> 1111 | N35: =F35 -> 5115 | O35: =L35+N35 -> 6226 | P35: 859 | R35: 4304 | T35: - | U35: - | V35: =P35 -> 859 | X35: =R35 -> 4304 | Z35: - | AB35: 1775 | AF35: 2005 | AG35: Juin
B36: 2005 | C36: July | D36: 1307 | F36: 6428 | H36: - | J36: - | L36: =D36 -> 1307 | N36: =F36 -> 6428 | O36: =L36+N36 -> 7735 | P36: 1023 | R36: 6499 | T36: - | U36: - | V36: =P36 -> 1023 | X36: =R36 -> 6499 | Z36: - | AB36: 2984 | AF36: 2005 | AG36: Juil
B37: 2005 | C37: Aug | D37: 1168 | F37: 5394 | H37: - | J37: - | L37: =D37 -> 1168 | N37: =F37 -> 5394 | O37: =L37+N37 -> 6562 | P37: 1122 | R37: 5777 | T37: - | U37: - | V37: =P37 -> 1122 | X37: =R37 -> 5777 | Z37: - | AB37: 9350 | AF37: 2005 | AG37: Aoû
B38: 2005 | C38: Sep | D38: 1034 | F38: 6685 | H38: - | J38: - | L38: =D38 -> 1034 | N38: =F38 -> 6685 | O38: =L38+N38 -> 7719 | P38: 981 | R38: 6257 | T38: - | U38: - | V38: =P38 -> 981 | X38: =R38 -> 6257 | Z38: - | AB38: 4683 | AF38: 2005 | AG38: Sep
B39: 2005 | C39: Oct | D39: 1008 | F39: 5897 | H39: - | J39: - | L39: =D39 -> 1008 | N39: =F39 -> 5897 | O39: =L39+N39 -> 6905 | P39: 1006 | R39: 6502 | T39: - | U39: - | V39: =P39 -> 1006 | X39: =R39 -> 6502 | Z39: - | AB39: 6823 | AF39: 2005 | AG39: Oct
B40: 2005 | C40: Nov | D40: 1195 | F40: 5544 | H40: - | J40: - | L40: =D40 -> 1195 | N40: =F40 -> 5544 | O40: =L40+N40 -> 6739 | P40: 1250 | R40: 4830 | T40: - | U40: - | V40: =P40 -> 1250 | X40: =R40 -> 4830 | Z40: - | AB40: 2371 | AF40: 2005 | AG40: Nov
B41: 2005 | C41: Dec | D41: 1453 | F41: 6177 | H41: - | J41: - | L41: =D41 -> 1453 | N41: =F41 -> 6177 | O41: =L41+N41 -> 7630 | P41: 1815 | R41: 5076 | T41: - | U41: - | V41: =P41 -> 1815 | X41: =R41 -> 5076 | Z41: - | AB41: 4603 | AF41: 2005 | AG41: Déc
... B51: 2006 | C51: Oct | D51: 1212 | F51: 6239 | H51: - | J51: - | L51: =D51 -> 1212 | N51: =F51 -> 6239 | O51: =L51+N51 -> 7451 | P51: 1060 | R51: 7335 | T51: - | U51: - | V51: =P51 -> 1060 | X51: =R51 -> 7335 | Z51: - | AB51: 9204 | AF51: 2006 | AG51: Oct
...

Sheet Tab 2.Purpose of visit
B1: Table 2 : Visitor Arrivals by Purpose of Visit
B2: Tableau 2 : Arrivées de visiteurs selon le motif du voyage
B4: Year | C4: Month | D4: VISITORS/VISITEURS | Q4: DAY VISITORS | U4: Année | V4: Mois
Q5: VISITEURS D'UN JOUR
D6: Holidays | F6: Visiting Friends and relatives | H6: Business, Meetings/ Conferences | J6: Stop Over | L6: Others, Education, sports | M6: Not | O6: Total | Q6: Cruiseship | S6: Other
M7: Stated | O7: Visitors
D8: Vacances | F8: Visite à des amis et à la famille | H8: Affaires, réunions ou conférence | J8: Escale | L8: Autres, education, sport | M8: non | O8: Visiteurs global | Q8: Croisiéristes | S8: Autres
M9: spécifié
B10: 2005 | D10: =SUM(D32:D43) -> 48022 | E10: =SUM(E32:E43) -> 0 | F10: =SUM(F32:F43) -> 4467 | G10: =SUM(G32:G43) -> 0 | H10: =SUM(H32:H43) -> 8424 | I10: =SUM(I32:I43) -> 0 | J10: =SUM(J32:J43) -> 1343 | K10: =SUM(K32:K43) -> 0 | ... O10: =SUM(O32:O43) -> 62257 | U10: 2005
B11: 2006 | D11: =SUM(D44:D55) -> 53030 | E11: =SUM(E44:E55) -> 0 | F11: =SUM(F44:F55) -> 5061 | G11: =SUM(G44:G55) -> 0 | H11: =SUM(H44:H55) -> 9312 | I11: =SUM(I44:I55) -> 0 | J11: =SUM(J44:J55) -> 775 | K11: =SUM(K44:K55) -> 0 | ... O11: =SUM(O44:O55) -> 68178 | U11: 2006
B12: 2007 | D12: =SUM(D56:D67) -> 55382.007 | E12: =SUM(E56:E67) -> 0 | F12: =SUM(F56:F67) -> 5301.9456 | G12: =SUM(G56:G67) -> 0 | H12: =SUM(H56:H67) -> 10446.113 | I12: =SUM(I56:I67) -> 0 | J12: =SUM(J56:J67) -> 976.9348 | K12: =SUM(K56:K67) -> 0 | ... O12: =SUM(O56:O67) -> 78893 | U12: 2007
B13: 2008 | D13: =SUM(D68:D79) -> 70313.394 | F13: =SUM(F68:F79) -> 9783.8228 | H13: =SUM(H68:H79) -> 9965.407 | J13: =SUM(J68:J79) -> 594.37619 | L13: =SUM(L68:L79) -> 0 | O13: =SUM(O68:O79) -> 90657 | U13: 2008
B14: 2009 | D14: =SUM(D80:D91) -> 84956.752 | F14: =SUM(F80:F91) -> 5498.9336 | H14: =SUM(H80:H91) -> 9419.8013 | J14: =SUM(J80:J91) -> 510.09615 | L14: =SUM(L80:L91) -> 289.41699 | M14: =SUM(M80:M91) -> 0 | N14: =SUM(N80:N91) -> 0 | O14: =SUM(O80:O91) -> 100675 | U14: 2009
B15: 2010 | D15: =SUM(D92:D103) -> 80681.286 | F15: =SUM(F92:F103) -> 6078.8652 | H15: =SUM(H92:H103) -> 9615.2753 | J15: =SUM(J92:J103) -> 691.57339 | L15: =SUM(L92:L103) -> 113 | M15: =SUM(M92:M103) -> 0 | N15: =SUM(N92:N103) -> 0 | O15: =SUM(O92:O103) -> 97180 | U15: 2010
B16: 2011 | D16: =SUM(D104:D115) -> 75821 | F16: =SUM(F104:F115) -> 7320 | H16: =SUM(H104:H115) -> 9933 | J16: =SUM(J104:J115) -> 790 | L16: =SUM(L104:L115) -> 96 | M16: =SUM(M104:M115) -> 0 | N16: =SUM(N104:N115) -> 0 | O16: =SUM(O104:O115) -> 93960 | U16: 2011
B17: 2012 | D17: =SUM(D116:D127) -> 88085 | F17: =SUM(F116:F127) -> 7910 | H17: =SUM(H116:H127) -> 11294 | J17: =SUM(J116:J127) -> 602 | L17: =SUM(L116:L127) -> 270 | M17: =SUM(M116:M127) -> 0 | N17: =SUM(N116:N127) -> 833 | O17: =SUM(D17:L17) -> 108161 | U17: 2012
B18: 2013 | D18: =SUM(D128:D139) -> 89253 | F18: =SUM(F128:F139) -> 7755 | H18: =SUM(H128:H139) -> 9079 | J18: =SUM(J128:J139) -> 613 | L18: =SUM(L128:L139) -> 3409 | M18: =SUM(M128:M139) -> 0 | N18: =SUM(N128:N139) -> 0 | O18: =SUM(D18:L18) -> 110109 | U18: 2013
B19: 2014 | D19: =SUM(D140:D151) -> 86239 | F19: =SUM(F140:F151) -> 7672 | H19: =SUM(H140:H151) -> 8007 | J19: =SUM(J140:J151) -> 1022 | L19: =SUM(L140:L151) -> 5868 | M19: =SUM(M140:M151) -> 0 | N19: =SUM(N140:N151) -> 0 | O19: =SUM(D19:L19) -> 108808 | U19: 2014
B20: 2015 | D20: =SUM(D152:D163) -> 63625 | F20: =SUM(F152:F163) -> 8495 | H20: =SUM(H152:H163) -> 8687 | J20: =SUM(J152:J163) -> 336 | L20: =SUM(L152:L163) -> 8809 | M20: =SUM(M152:M163) -> 0 | N20: =SUM(N152:N163) -> 0 | O20: =SUM(D20:L20) -> 89952 | U20: 2015
B21: 2016 | D21: =SUM(D164:D175) -> 71088 | F21: =SUM(F164:F175) -> 8300 | H21: =SUM(H164:H175) -> 8521 | J21: =SUM(J164:J175) -> 551 | L21: =SUM(L164:L175) -> 6657 | M21: =SUM(M164:M175) -> 0 | N21: =SUM(N164:N175) -> 0 | O21: =SUM(D21:L21) -> 95117 | U21: 2016
B22: 2017 | D22: =SUM(D176:D187) -> 83465 | F22: =SUM(F176:F187) -> 8940 | H22: =SUM(H176:H187) -> 8338 | J22: =SUM(J176:J187) -> 897 | L22: =SUM(L176:L187) -> 7530 | M22: =SUM(M176:M187) -> 0 | N22: =SUM(N176:N187) -> 0 | O22: =SUM(O176:O187) -> 109170 | U22: 2017
B23: 2018 | D23: =SUM(D188:D199) -> 91726 | F23: =SUM(F188:F199) -> 8616 | H23: =SUM(H188:H199) -> 7552 | J23: =SUM(J188:J199) -> 645 | L23: =SUM(L188:L199) -> 7095 | M23: =SUM(M188:M199) -> 0 | N23: =SUM(N188:N199) -> 0 | O23: =SUM(O188:O199) -> 115634 | U23: 2018
B24: 2019 | D24: =SUM(D200:D211) -> 95849 | E24: =SUM(E200:E211) -> 0 | F24: =SUM(F200:F211) -> 8764 | H24: =SUM(H200:H211) -> 8059 | J24: =SUM(J200:J211) -> 524 | L24: =SUM(L200:L211) -> 7432 | M24: =SUM(M200:M211) -> 0 | N24: =SUM(N200:N211) -> 0 | O24: =SUM(O200:O211) -> 120628 | U24: 2019
B25: 2020 | D25: =SUM(D212:D223) -> 17166 | E25: =SUM(E212:E223) -> 0 | F25: =SUM(F212:F223) -> 1445 | H25: =SUM(H212:H223) -> 1085 | J25: =SUM(J212:J223) -> 448 | L25: =SUM(L212:L223) -> 1821 | M25: =SUM(M212:M223) -> 0 | N25: =SUM(N212:N223) -> 0 | O25: =SUM(O212:O223) -> 21965 | U25: 2020
B26: 2021 | D26: =SUM(D224:D235) -> 0 | F26: =SUM(F224:F235) -> 0 | H26: =SUM(H224:H235) -> 0 | J26: =SUM(J224:J235) -> 0 | L26: =SUM(L224:L235) -> 0 | M26: =SUM(M224:M235) -> 0 | N26: =SUM(N224:N235) -> 0 | O26: =SUM(O224:O235) -> 0 | U26: 2021
B27: 2022 | D27: =SUM(D236:D247) -> 23859 | F27: =SUM(F236:F247) -> 3202 | H27: =SUM(H236:H247) -> 1757 | J27: =SUM(J236:J247) -> 204 | L27: =SUM(L236:L247) -> 1352 | M27: =SUM(M236:M247) -> 0 | N27: =SUM(N236:N247) -> 0 | O27: =SUM(O236:O247) -> 30374 | U27: 2022
B28: 2023 | D28: =SUM(D248:D259) -> 66478 | E28: =SUM(E248:E259) -> 0 | F28: =SUM(F248:F259) -> 3870 | H28: =SUM(H248:H259) -> 2705 | J28: =SUM(J248:J259) -> 742 | L28: =SUM(L248:L259) -> 3204 | M28: =SUM(M248:M259) -> 0 | N28: =SUM(N248:N259) -> 0 | O28: =SUM(O248:O259) -> 76999 | U28: 2023
B29: 2024 | D29: =SUM(D260:D271) -> 43431 | E29: =SUM(E260:E271) -> 0 | F29: =SUM(F260:F271) -> 4791 | H29: =SUM(H260:H271) -> 4180 | J29: =SUM(J260:J271) -> 500 | L29: =SUM(L260:L271) -> 6176 | M29: =SUM(M260:M271) -> 0 | N29: =SUM(N260:N271) -> 0 | O29: =SUM(O260:O271) -> 59078 | U29: 2024
B30: 2025 | D30: =SUM(D272:D283) -> 74631 | E30: =SUM(E272:E283) -> 0 | F30: =SUM(F272:F283) -> 6094 | H30: =SUM(H272:H283) -> 4898 | J30: =SUM(J272:J283) -> 808 | L30: =SUM(L272:L283) -> 9488 | M30: =SUM(M272:M283) -> 0 | N30: =SUM(N272:N283) -> 0 | O30: =SUM(O272:O283) -> 95919 | U30: 2025
B32: 2005 | C32: Jan | D32: 4024 | F32: 272 | H32: 515 | J32: 169 | L32: 0 | M32: - | O32: =SUM(D32:M32) -> 4980 | Q32: 7585 | S32: - | U32: 2005 | V32: Jan
B33: 2005 | C33: Feb | D33: 2567 | F33: 180 | H33: 599 | J33: 79 | L33: 0 | M33: - | O33: =SUM(D33:M33) -> 3425 | Q33: 3533 | S33: - | U33: 2005 | V33: Fév
B34: 2005 | C34: Mar | D34: 3034 | F34: 352 | H34: 683 | J34: 145 | L34: 0 | M34: - | O34: =SUM(D34:M34) -> 4214 | Q34: 7016 | S34: - | U34: 2005 | V34: Mar
B35: 2005 | C35: Apr | D35: 3090 | F35: 281 | H35: 669 | J35: 146 | L35: 0 | M35: - | O35: =SUM(D35:M35) -> 4186 | Q35: 7949 | S35: - | U35: 2005 | V35: Avr
B36: 2005 | C36: May | D36: 2999 | F36: 245 | H36: 730 | J36: 34 | L36: 0 | M36: - | O36: =SUM(D36:M36) -> 4008 | Q36: 3562 | S36: - | U36: 2005 | V36: Mai
B37: 2005 | C37: Jun | D37: 3784 | F37: 542 | H37: 626 | J37: 163 | L37: 0 | M37: - | O37: =SUM(D37:M37) -> 5115 | Q37: 1775 | S37: - | U37: 2005 | V37: Juin
B38: 2005 | C38: July | D38: 4630 | F38: 648 | H38: 1031 | J38: 119 | L38: 0 | M38: - | O38: =SUM(D38:M38) -> 6428 | Q38: 2984 | S38: - | U38: 2005 | V38: Juil
B39: 2005 | C39: Aug | D39: 3928 | F39: 426 | H39: 898 | J39: 142 | L39: 0 | M39: - | O39: =SUM(D39:M39) -> 5394 | Q39: 9350 | S39: - | U39: 2005 | V39: Aoû
B40: 2005 | C40: Sep | D40: 5546 | F40: 240 | H40: 790 | J40: 109 | L40: 0 | M40: - | O40: =SUM(D40:M40) -> 6685 | Q40: 4683 | S40: - | U40: 2005 | V40: Sep
B41: 2005 | C41: Oct | D41: 5022 | F41: 241 | H41: 732 | J41: 106 | L41: 0 | M41: - | O41: =SUM(D41:M41) -> 6101 | Q41: 6823 | S41: - | U41: 2005 | V41: Oct
B42: 2005 | C42: Nov | D42: 4425 | F42: 338 | H42: 698 | J42: 82 | L42: 0 | M42: 1 | O42: =SUM(D42:M42) -> 5544 | Q42: 2371 | S42: - | U42: 2005 | V42: Nov
...

Sheet Tab 3.Count of usual residence
B1: Table 3 : Visitor Arrivals by Usual Country of Residence
B2: Tableau 3 : Arrivées des visiteurs par pays de résidence habituelle
D4: Australia | F4: New Zealand | H4: New Caledonia | J4: Other Pacific Countries | L4: Europe | N4: North America | P4: Japan | R4: China | T4: Other Countries | W4: TOTAL
B7: Year | C7: Month | D7: Australie | F7: Nouvelle- | H7: Nouvelle- | J7: Autres Pays | N7: Amérique | P7: Japon | R7: Chine | T7: Autres | Y7: Année | Z7: Mois
F8: Zélande | H8: Calédonie | J8: du Pacifique | N8: du Nord | T8: pays
B9: 2005 | D9: =SUM(D31:D42) -> 38190 | E9: =SUM(E31:E42) -> 0 | F9: =SUM(F31:F42) -> 7700 | G9: =SUM(G31:G42) -> 0 | H9: =SUM(H31:H42) -> 6817 | I9: =SUM(I31:I42) -> 0 | J9: =SUM(J31:J42) -> 2735 | K9: =SUM(K31:K42) -> 0 | ... W9: =SUM(W31:W42) -> 62285 | Y9: 2005
B10: 2006 | D10: =SUM(D43:D54) -> 40385 | E10: =SUM(E43:E54) -> 0 | F10: =SUM(F43:F54) -> 9821 | G10: =SUM(G43:G54) -> 0 | H10: =SUM(H43:H54) -> 7480 | I10: =SUM(I43:I54) -> 0 | J10: =SUM(J43:J54) -> 2681 | K10: =SUM(K43:K54) -> 0 | ... W10: =SUM(W43:W54) -> 68179 | Y10: 2006
B11: 2007 | D11: =SUM(D55:D66) -> 41951.783 | E11: =SUM(E55:E66) -> 0 | F11: =SUM(F55:F66) -> 12438.468 | G11: =SUM(G55:G66) -> 0 | H11: =SUM(H55:H66) -> 7140.063 | I11: =SUM(I55:I66) -> 0 | J11: =SUM(J55:J66) -> 2437.8227 | K11: =SUM(K55:K66) -> 0 | ... W11: =SUM(W55:W66) -> 72107 | Y11: 2007
B12: 2008 | D12: =SUM(D67:D78) -> 53250.717 | F12: =SUM(F67:F78) -> 13915.822 | H12: =SUM(H67:H78) -> 9647.9864 | J12: =SUM(J67:J78) -> 3758.9017 | L12: =SUM(L67:L78) -> 4887.134 | N12: =SUM(N67:N78) -> 2578.4763 | P12: =SUM(P67:P78) -> 590.24076 | R12: =SUM(R67:R78) -> 0 | T12: =SUM(T67:T78) -> 2027.7217 | U12: =SUM(U67:U78) -> 0 | W12: =SUM(W67:W78) -> 90657 | Y12: 2008
B13: 2009 | D13: =SUM(D79:D90) -> 64908.577 | F13: =SUM(F79:F90) -> 12606.533 | H13: =SUM(H79:H90) -> 9155.1666 | J13: =SUM(J79:J90) -> 3707.7812 | L13: =SUM(L79:L90) -> 4889.5757 | N13: =SUM(N79:N90) -> 2549.2553 | P13: =SUM(P79:P90) -> 642.28423 | R13: 573 | T13: 1642.8272 | U13: =SUM(U79:U90) -> 0 | W13: =SUM(W79:W90) -> 100675 | Y13: 2009
B14: 2010 | D14: =SUM(D91:D102) -> 58760.113 | F14: =SUM(F91:F102) -> 11927.074 | H14: =SUM(H91:H102) -> 11410.125 | J14: =SUM(J91:J102) -> 4719.2827 | L14: =SUM(L91:L102) -> 4887.6704 | N14: =SUM(N91:N102) -> 2394.5595 | P14: =SUM(P91:P102) -> 517.19331 | R14: 693 | T14: 1870.9819 | U14: =SUM(U91:U102) -> 0 | W14: =SUM(W91:W102) -> 97180 | Y14: 2010
B15: 2011 | D15: =SUM(D103:D114) -> 57843 | F15: =SUM(F103:F114) -> 11399 | H15: =SUM(H103:H114) -> 11376 | J15: =SUM(J103:J114) -> 3397 | L15: =SUM(L103:L114) -> 5265 | N15: =SUM(N103:N114) -> 1922 | P15: =SUM(P103:P114) -> 630 | R15: 581 | T15: 1547 | U15: =SUM(U103:U114) -> 0 | W15: =SUM(W103:W114) -> 93960 | Y15: 2011
B16: 2012 | D16: =SUM(D115:D126) -> 65405 | F16: =SUM(F115:F126) -> 14430 | H16: =SUM(H115:H126) -> 13138 | J16: =SUM(J115:J126) -> 4313 | L16: =SUM(L115:L126) -> 5491 | N16: =SUM(N115:N126) -> 2094 | P16: =SUM(P115:P126) -> 705 | R16: 623 | T16: 1962 | U16: =SUM(U115:U126) -> 0 | W16: =SUM(D16:T16) -> 108161 | Y16: 2012
B17: 2013 | D17: =SUM(D127:D138) -> 65776 | F17: =SUM(F127:F138) -> 15068 | H17: =SUM(H127:H138) -> 12515 | J17: =SUM(J127:J138) -> 4874 | L17: =SUM(L127:L138) -> 5544 | N17: =SUM(N127:N138) -> 2614 | P17: =SUM(P127:P138) -> 659 | R17: 1062 | T17: 1997 | U17: =SUM(U127:U138) -> 0 | W17: =SUM(D17:T17) -> 110109 | Y17: 2013
B18: 2014 | D18: =SUM(D139:D150) -> 60808 | F18: =SUM(F139:F150) -> 16293 | H18: =SUM(H139:H150) -> 12756 | J18: =SUM(J139:J150) -> 6630 | L18: =SUM(L139:L150) -> 5591 | M18: =SUM(M139:M150) -> 0 | N18: =SUM(N139:N150) -> 2373 | P18: =SUM(P139:P150) -> 763 | Q18: =SUM(Q139:Q150) -> 0 | R18: 1563 | T18: 2031 | U18: =SUM(U139:U150) -> 0 | W18: =SUM(D18:T18) -> 108808 | Y18: 2014
B19: 2015 | D19: =SUM(D151:D162) -> 46098 | F19: =SUM(F151:F162) -> 13422 | H19: =SUM(H151:H162) -> 10567 | J19: =SUM(J151:J162) -> 5953 | L19: =SUM(L151:L162) -> 5839 | N19: =SUM(N151:N162) -> 2962 | P19: =SUM(P151:P162) -> 633 | R19: =SUM(R151:R162) -> 2186 | T19: =SUM(T151:T162) -> 2292 | W19: =SUM(D19:T19) -> 89952 | Y19: 2015
B20: 2016 | D20: =SUM(D163:D174) -> 49752 | F20: =SUM(F163:F174) -> 10931 | H20: =SUM(H163:H174) -> 9681 | J20: =SUM(J163:J174) -> 5705 | L20: =SUM(L163:L174) -> 10067 | N20: =SUM(N163:N174) -> 2893 | P20: =SUM(P163:P174) -> 903 | R20: =SUM(R163:R174) -> 2736 | T20: =SUM(T163:T174) -> 2449 | W20: =SUM(D20:T20) -> 95117 | Y20: 2016
B21: 2017 | D21: =SUM(D175:D186) -> 57387 | F21: =SUM(F175:F186) -> 11554 | H21: =SUM(H175:H186) -> 15880 | J21: =SUM(J175:J186) -> 7147 | L21: =SUM(L175:L186) -> 6806 | N21: =SUM(N175:N186) -> 3016 | P21: =SUM(P175:P186) -> 1076 | R21: =SUM(R175:R186) -> 3612 | T21: =SUM(T175:T186) -> 2692 | W21: =SUM(W175:W186) -> 109170 | Y21: 2017
B22: 2018 | D22: =SUM(D187:D198) -> 60616 | E22: =SUM(E187:E198) -> 0 | F22: =SUM(F187:F198) -> 13432 | G22: =SUM(G187:G198) -> 0 | H22: =SUM(H187:H198) -> 15105 | J22: =SUM(J187:J198) -> 6545 | K22: =SUM(K187:K198) -> 0 | L22: =SUM(L187:L198) -> 8023 | M22: =SUM(M187:M198) -> 0 | N22: =SUM(N187:N198) -> 3347 | O22: =SUM(O187:O198) -> 0 | P22: =SUM(P187:P198) -> 963 | Q22: =SUM(Q187:Q198) -> 0 | R22: =SUM(R187:R198) -> 4007 | T22: =SUM(T187:T198) -> 3596 | W22: =SUM(W187:W198) -> 115634 | Y22: 2018
B23: 2019 | D23: =SUM(D199:D210) -> 63122 | E23: =SUM(E199:E210) -> 0 | F23: =SUM(F199:F210) -> 15085 | G23: =SUM(G199:G210) -> 0 | H23: =SUM(H199:H210) -> 14738 | J23: =SUM(J199:J210) -> 6560 | K23: =SUM(K199:K210) -> 0 | L23: =SUM(L199:L210) -> 8992 | M23: =SUM(M199:M210) -> 0 | N23: =SUM(N199:N210) -> 3120 | O23: =SUM(O199:O210) -> 0 | P23: =SUM(P199:P210) -> 1107 | Q23: =SUM(Q199:Q210) -> 0 | R23: =SUM(R199:R210) -> 4671 | T23: =SUM(T199:T210) -> 3233 | V23: =SUM(V199:V210) -> 0 | W23: =SUM(W199:W210) -> 120628 | Y23: 2019
B24: 2020 | D24: =SUM(D211:D222) -> 11248 | E24: =SUM(E211:E222) -> 0 | F24: =SUM(F211:F222) -> 1819 | G24: =SUM(G211:G222) -> 0 | H24: =SUM(H211:H222) -> 3778 | J24: =SUM(J211:J222) -> 1241 | K24: =SUM(K211:K222) -> 0 | L24: =SUM(L211:L222) -> 1728 | M24: =SUM(M211:M222) -> 0 | N24: =SUM(N211:N222) -> 692 | O24: =SUM(O211:O222) -> 0 | P24: =SUM(P211:P222) -> 171 | Q24: =SUM(Q211:Q222) -> 0 | R24: =SUM(R211:R222) -> 680 | T24: =SUM(T211:T222) -> 608 | V24: =SUM(V211:V222) -> 0 | W24: =SUM(W211:W222) -> 21965 | Y24: 2020
B25: 2021 | D25: =SUM(D223:D234) -> 0 | F25: =SUM(F223:F234) -> 0 | H25: =SUM(H223:H234) -> 0 | J25: =SUM(J223:J234) -> 0 | L25: =SUM(L223:L234) -> 0 | N25: =SUM(N223:N234) -> 0 | P25: =SUM(P223:P234) -> 0 | R25: =SUM(R223:R234) -> 0 | T25: =SUM(T223:T234) -> 0 | V25: =SUM(V223:V234) -> 0 | W25: =SUM(W223:W234) -> 0 | Y25: 2021
B26: 2022 | D26: =SUM(D235:D246) -> 17460 | E26: =SUM(E235:E246) -> 0 | F26: =SUM(F235:F246) -> 4124 | G26: =SUM(G235:G246) -> 0 | H26: =SUM(H235:H246) -> 3224 | I26: =SUM(I235:I246) -> 0 | J26: =SUM(J235:J246) -> 1613 | K26: =SUM(K235:K246) -> 0 | ... W26: =SUM(W235:W246) -> 30373 | Y26: 2022
B27: 2023 | D27: =SUM(D247:D258) -> 45232 | E27: =SUM(E247:E258) -> 0 | F27: =SUM(F247:F258) -> 8536 | G27: =SUM(G247:G258) -> 0 | H27: =SUM(H247:H258) -> 6347 | I27: =SUM(I247:I258) -> 0 | J27: =SUM(J247:J258) -> 3177 | K27: =SUM(K247:K258) -> 0 | ... W27: =SUM(W247:W258) -> 76999 | Y27: 2023
B28: 2024 | D28: =SUM(D259:D270) -> 33450 | E28: =SUM(E259:E270) -> 0 | F28: =SUM(F259:F270) -> 4738 | G28: =SUM(G259:G270) -> 0 | H28: =SUM(H259:H270) -> 1349 | I28: =SUM(I259:I270) -> 0 | J28: =SUM(J259:J270) -> 3791 | K28: =SUM(K259:K270) -> 0 | ... W28: =SUM(W259:W270) -> 59078 | Y28: 2024
B29: 2025 | D29: =SUM(D271:D282) -> 58922 | E29: =SUM(E271:E282) -> 0 | F29: =SUM(F271:F282) -> 6046 | G29: =SUM(G271:G282) -> 0 | H29: =SUM(H271:H282) -> 2827 | I29: =SUM(I271:I282) -> 0 | J29: =SUM(J271:J282) -> 5285 | K29: =SUM(K271:K282) -> 0 | ... W29: =SUM(W271:W282) -> 95919 | Y29: 2025
B31: 2005 | C31: Jan | D31: 2967 | F31: 373 | H31: 785 | J31: 352 | L31: 273 | N31: 111 | P31: 50 | R31: - | T31: 83 | W31: =SUM(D31:U31) -> 4994 | Y31: 2005 | Z31: Jan
B32: 2005 | C32: Feb | D32: 2107 | F32: 180 | H32: 500 | J32: 245 | L32: 195 | N32: 80 | P32: 34 | R32: - | T32: 99 | W32: =SUM(D32:U32) -> 3440 | Y32: 2005 | Z32: Fév
B33: 2005 | C33: Mar | D33: 2790 | F33: 390 | H33: 306 | J33: 255 | L33: 202 | N33: 166 | P33: 29 | R33: - | T33: 76 | W33: =SUM(D33:U33) -> 4214 | Y33: 2005 | Z33: Mar
B34: 2005 | C34: Apr | D34: 2914 | F34: 471 | H34: 305 | J34: 111 | L34: 206 | N34: 82 | P34: 45 | R34: - | T34: 52 | W34: =SUM(D34:U34) -> 4186 | Y34: 2005 | Z34: Avr
B35: 2005 | C35: May | D35: 2360 | F35: 485 | H35: 494 | J35: 151 | L35: 230 | N35: 123 | P35: 39 | R35: - | T35: 126 | W35: =SUM(D35:U35) -> 4008 | Y35: 2005 | Z35: Mai
B36: 2005 | C36: Jun | D36: 3164 | F36: 881 | H36: 410 | J36: 143 | L36: 264 | N36: 140 | P36: 52 | R36: - | T36: 61 | W36: =SUM(D36:U36) -> 5115 | Y36: 2005 | Z36: Juin
B37: 2005 | C37: July | D37: 3564 | F37: 966 | H37: 870 | J37: 273 | L37: 460 | N37: 153 | P37: 57 | R37: - | T37: 85 | W37: =SUM(D37:U37) -> 6428 | Y37: 2005 | Z37: Juil
B38: 2005 | C38: Aug | D38: 2963 | F38: 881 | H38: 514 | J38: 201 | L38: 435 | N38: 202 | P38: 68 | R38: - | T38: 130 | W38: =SUM(D38:U38) -> 5394 | Y38: 2005 | Z38: Aoû
B39: 2005 | C39: Sep | D39: 4167 | F39: 896 | H39: 665 | J39: 379 | L39: 272 | N39: 135 | P39: 70 | R39: - | T39: 101 | W39: =SUM(D39:U39) -> 6685 | Y39: 2005 | Z39: Sep
B40: 2005 | C40: Oct | D40: 3818 | F40: 986 | H40: 502 | J40: 216 | L40: 326 | N40: 137 | P40: 30 | R40: - | T40: 86 | W40: =SUM(D40:U40) -> 6101 | Y40: 2005 | Z40: Oct
B41: 2005 | C41: Nov | D41: 3452 | F41: 595 | H41: 648 | J41: 190 | L41: 344 | N41: 148 | P41: 61 | R41: - | T41: 106 | W41: =SUM(D41:U41) -> 5544 | Y41: 2005 | Z41: Nov
B42: 2005 | C42: Dec | D42: 3924 | F42: 596 | H42: 818 | J42: 219 | L42: 309 | N42: 160 | P42: 49 | R42: - | T42: 101 | W42: =SUM(D42:U42) -> 6176 | Y42: 2005 | Z42: Déc
... B62: 2007 | C62: Aug | D62: 3784.5273 | F62: 1471.9884 | H62: 660.13965 | J62: 202.96219 | L62: 465.37795 | N62: 264.46588 | P62: 68.679125 | R62: - | T62: 157.85948 | W62: =SUM(D62:U62) -> 7076 | Y62: 2007 | Z62: Aoû
B63: 2007 | C63: Sep | D63: na | F63: na | H63: na | J63: na | L63: na | N63: na | P63: na | R63: na | T63: na | W63: na | Y63: 2007 | Z63: Sep
...

Sheet T4.Resident Arr by nationality
B1: Table 4 : Overseas Arrivals of Residents by Nationality
B2: Tableau 4 : Arrivées des résidents par nationalité
L5: New | P5: Pacific | R5: North | T5: Other | U5: Not
D6: Ni-Vanuatu | F6: Australian | H6: French | J6: British | L6: Zealander | N6: Asian | P6: Islanders | R6: Americans | T6: countries | U6: Stated | X6: TOTAL
B8: Year | C8: Month | F8: Australien | H8: Français | J8: Anglais | L8: Néo- | N8: Asiatiques | P8: Autres pays | R8: Américain | T8: Autres | U8: Non | Z8: Année | AA8: Mois
L9: Zélandais | P9: du Pacifique | R9: du Nord | T9: pays | U9: spécifié
B10: 2005 | D10: =SUM(D32:D43) -> 7588 | F10: =SUM(F32:F43) -> 2575 | H10: =SUM(H32:H43) -> 1374 | J10: =SUM(J32:J43) -> 215 | L10: =SUM(L32:L43) -> 755 | N10: =SUM(N32:N43) -> 322 | P10: =SUM(P32:P43) -> 486 | R10: =SUM(R32:R43) -> 304 | T10: =SUM(T32:T43) -> 192 | U10: =SUM(U32:U43) -> 4 | V10: =SUM(V32:V43) -> 0 | X10: =SUM(X32:X43) -> 13815
B11: 2006 | D11: =SUM(D44:D55) -> 7380 | F11: =SUM(F44:F55) -> 3280 | H11: =SUM(H44:H55) -> 1372 | J11: =SUM(J44:J55) -> 231 | L11: =SUM(L44:L55) -> 1017 | N11: =SUM(N44:N55) -> 373 | P11: =SUM(P44:P55) -> 675 | R11: =SUM(R44:R55) -> 400 | T11: =SUM(T44:T55) -> 198 | U11: =SUM(U44:U55) -> 0 | V11: =SUM(V44:V55) -> 0 | X11: =SUM(X44:X55) -> 14926
B12: 2007 | D12: =SUM(D56:D67) -> 7227.3649 | F12: =SUM(F56:F67) -> 2885.5316 | H12: =SUM(H56:H67) -> 1271.0524 | J12: =SUM(J56:J67) -> 99.952396 | L12: =SUM(L56:L67) -> 963.03103 | N12: =SUM(N56:N67) -> 288.1246 | P12: =SUM(P56:P67) -> 400.28339 | R12: =SUM(R56:R67) -> 430.67531 | T12: =SUM(T56:T67) -> 152.98438 | U12: =SUM(U56:U67) -> 0 | V12: =SUM(V56:V67) -> 0 | X12: =SUM(X56:X67) -> 13719
B13: 2008
B14: 2009 | D14: =SUM(D80:D91) -> 11527.098 | F14: =SUM(F80:F91) -> 3378.1336 | H14: =SUM(H80:H91) -> 1736.0463 | J14: =SUM(J80:J91) -> 135.66575 | L14: =SUM(L80:L91) -> 1246.243 | N14: =SUM(N80:N91) -> 405.7292 | P14: =SUM(P80:P91) -> 566.53326 | R14: =SUM(R80:R91) -> 412.24178 | T14: =SUM(T80:T91) -> 274.93684 | U14: =SUM(U80:U91) -> 0 | V14: =SUM(V80:V91) -> 0 | X14: =SUM(X80:X91) -> 19682.628 | Z14: 2009
B15: 2010 | D15: =SUM(D92:D103) -> 11794.391 | F15: =SUM(F92:F103) -> 3699.5536 | H15: =SUM(H92:H103) -> 1894.2069 | J15: =SUM(J92:J103) -> 132.11937 | L15: =SUM(L92:L103) -> 1436.2447 | N15: =SUM(N92:N103) -> 503.55873 | P15: =SUM(P92:P103) -> 767.73488 | R15: =SUM(R92:R103) -> 495.8249 | T15: =SUM(T92:T103) -> 329.51095 | U15: =SUM(U92:U103) -> 0 | V15: =SUM(V92:V103) -> 0 | X15: =SUM(X92:X103) -> 21053.145 | Z15: 2010
B16: 2011 | D16: =SUM(D104:D115) -> 12508 | F16: =SUM(F104:F115) -> 3867 | H16: =SUM(H104:H115) -> 1802 | J16: =SUM(J104:J115) -> 244 | L16: =SUM(L104:L115) -> 1370 | N16: =SUM(N104:N115) -> 719 | P16: =SUM(P104:P115) -> 1090 | R16: =SUM(R104:R115) -> 352 | T16: =SUM(T104:T115) -> 321 | U16: =SUM(U104:U115) -> 0 | V16: =SUM(V104:V115) -> 0 | X16: =SUM(X104:X115) -> 22273 | Z16: 2011
B17: 2012 | D17: =SUM(D116:D127) -> 14317 | F17: =SUM(F116:F127) -> 3629 | H17: =SUM(H116:H127) -> 1526 | J17: =SUM(J116:J127) -> 203 | L17: =SUM(L116:L127) -> 1236 | N17: =SUM(N116:N127) -> 696 | P17: =SUM(P116:P127) -> 686 | R17: =SUM(R116:R127) -> 370 | T17: =SUM(T116:T127) -> 295 | U17: =SUM(U116:U127) -> 0 | V17: =SUM(V116:V127) -> 0 | X17: =SUM(X116:X127) -> 22958 | Z17: 2012
B18: 2013 | D18: =SUM(D128:D139) -> 15410 | F18: =SUM(F128:F139) -> 4096 | H18: =SUM(H128:H139) -> 1782 | J18: =SUM(J128:J139) -> 167 | L18: =SUM(L128:L139) -> 1293 | N18: =SUM(N128:N139) -> 915 | P18: =SUM(P128:P139) -> 1007 | R18: =SUM(R128:R139) -> 566 | T18: =SUM(T128:T139) -> 375 | U18: =SUM(U128:U139) -> 0 | V18: =SUM(V128:V139) -> 0 | X18: =SUM(X128:X139) -> 25611 | Z18: 2013
B19: 2014 | D19: =SUM(D140:D151) -> 15044 | F19: =SUM(F140:F151) -> 4297 | H19: =SUM(H140:H151) -> 1934 | J19: =SUM(J140:J151) -> 104 | L19: =SUM(L140:L151) -> 1274 | N19: =SUM(N140:N151) -> 966 | P19: =SUM(P140:P151) -> 1161 | R19: =SUM(R140:R151) -> 690 | T19: =SUM(T140:T151) -> 414 | U19: =SUM(U140:U151) -> 0 | V19: =SUM(V140:V151) -> 0 | X19: =SUM(X140:X151) -> 25884 | Z19: 2014
B20: 2015 | D20: =SUM(D152:D163) -> 17406 | F20: =SUM(F152:F163) -> 3557 | H20: =SUM(H152:H163) -> 1672 | J20: =SUM(J152:J163) -> 95 | L20: =SUM(L152:L163) -> 1206 | N20: =SUM(N152:N163) -> 1008 | P20: =SUM(P152:P163) -> 1045 | R20: =SUM(R152:R163) -> 569 | T20: =SUM(T152:T163) -> 404 | U20: =SUM(U152:U163) -> 0 | V20: =SUM(V152:V163) -> 0 | X20: =SUM(X152:X163) -> 26962 | Z20: 2015
B21: 2016 | D21: =SUM(D164:D175) -> 18511 | F21: =SUM(F164:F175) -> 2516 | H21: =SUM(H164:H175) -> 1120 | J21: =SUM(J164:J175) -> 164 | L21: =SUM(L164:L175) -> 855 | N21: =SUM(N164:N175) -> 741 | P21: =SUM(P164:P175) -> 645 | R21: =SUM(R164:R175) -> 343 | T21: =SUM(T164:T175) -> 264 | U21: =SUM(U164:U175) -> 0 | V21: =SUM(V164:V175) -> 0 | X21: =SUM(X164:X175) -> 25160 | Z21: 2016
B22: 2017 | D22: =SUM(D176:D187) -> 21967 | F22: =SUM(F176:F187) -> 2463 | H22: =SUM(H176:H187) -> 1036 | J22: =SUM(J176:J187) -> 118 | L22: =SUM(L176:L187) -> 797 | N22: =SUM(N176:N187) -> 712 | P22: =SUM(P176:P187) -> 564 | R22: =SUM(R176:R187) -> 358 | T22: =SUM(T176:T187) -> 233 | U22: =SUM(U176:U187) -> 0 | V22: =SUM(V176:V187) -> 0 | X22: =SUM(X176:X187) -> 28248 | Z22: 2017
B23: 2018 | D23: =SUM(D188:D199) -> 23610 | F23: =SUM(F188:F199) -> 1919 | G23: =SUM(G188:G199) -> 0 | H23: =SUM(H188:H199) -> 750 | J23: =SUM(J188:J199) -> 97 | L23: =SUM(L188:L199) -> 591 | N23: =SUM(N188:N199) -> 875 | P23: =SUM(P188:P199) -> 593 | R23: =SUM(R188:R199) -> 273 | T23: =SUM(T188:T199) -> 228 | U23: =SUM(U188:U199) -> 0 | V23: =SUM(V188:V199) -> 0 | X23: =SUM(X188:X199) -> 28936 | Z23: 2018
B24: 2019 | D24: =SUM(D200:D211) -> 26317 | F24: =SUM(F200:F211) -> 2344 | G24: =SUM(G200:G211) -> 0 | H24: =SUM(H200:H211) -> 884 | J24: =SUM(J200:J211) -> 329 | L24: =SUM(L200:L211) -> 780 | N24: =SUM(N200:N211) -> 2809 | P24: =SUM(P200:P211) -> 665 | R24: =SUM(R200:R211) -> 409 | T24: =SUM(T200:T211) -> 364 | U24: =SUM(U200:U211) -> 0 | V24: =SUM(V200:V211) -> 0 | X24: =SUM(X200:X211) -> 34901 | Z24: 2019
B25: 2020 | D25: =SUM(D212:D223) -> 8374 | F25: =SUM(F212:F223) -> 719 | H25: =SUM(H212:H223) -> 285 | J25: =SUM(J212:J223) -> 42 | L25: =SUM(L212:L223) -> 243 | N25: =SUM(N212:N223) -> 283 | P25: =SUM(P212:P223) -> 273 | R25: =SUM(R212:R223) -> 87 | T25: =SUM(T212:T223) -> 103 | U25: =SUM(U212:U223) -> 0 | V25: =SUM(V212:V223) -> 0 | X25: =SUM(X212:X223) -> 10409 | Z25: 2020
B26: 2021 | D26: =SUM(D224:D235) -> 2659 | F26: =SUM(F224:F235) -> 343 | H26: =SUM(H224:H235) -> 63 | J26: =SUM(J224:J235) -> 10 | L26: =SUM(L224:L235) -> 79 | N26: =SUM(N224:N235) -> 210 | P26: =SUM(P224:P235) -> 67 | R26: =SUM(R224:R235) -> 17 | T26: =SUM(T224:T235) -> 47 | U26: =SUM(U224:U235) -> 0 | V26: =SUM(V224:V235) -> 0 | X26: =SUM(X224:X235) -> 3495 | Z26: 2021
B27: 2022 | D27: =SUM(D236:D247) -> 15012 | F27: =SUM(F236:F247) -> 1501 | H27: =SUM(H236:H247) -> 381 | J27: =SUM(J236:J247) -> 89 | L27: =SUM(L236:L247) -> 297 | N27: =SUM(N236:N247) -> 562 | P27: =SUM(P236:P247) -> 392 | R27: =SUM(R236:R247) -> 152 | T27: =SUM(T236:T247) -> 155 | U27: =SUM(U236:U247) -> 0 | V27: =SUM(V236:V247) -> 0 | X27: =SUM(X236:X247) -> 18541 | Z27: 2022
B28: 2023 | D28: =SUM(D248:D259) -> 26750 | F28: =SUM(F248:F259) -> 972 | H28: =SUM(H248:H259) -> 287 | J28: =SUM(J248:J259) -> 29 | L28: =SUM(L248:L259) -> 292 | N28: =SUM(N248:N259) -> 602 | P28: =SUM(P248:P259) -> 279 | R28: =SUM(R248:R259) -> 92 | T28: =SUM(T248:T259) -> 131 | U28: =SUM(U248:U259) -> 0 | V28: =SUM(V248:V259) -> 0 | X28: =SUM(X248:X259) -> 29434 | Z28: 2023
B29: 2024 | D29: =SUM(D260:D271) -> 24047 | F29: =SUM(F260:F271) -> 1785 | G29: =SUM(G260:G271) -> 0 | H29: =SUM(H260:H271) -> 598 | J29: =SUM(J260:J271) -> 79 | L29: =SUM(L260:L271) -> 496 | N29: =SUM(N260:N271) -> 1652 | P29: =SUM(P260:P271) -> 756 | R29: =SUM(R260:R271) -> 168 | T29: =SUM(T260:T271) -> 343 | U29: =SUM(U260:U271) -> 0 | V29: =SUM(V260:V271) -> 0 | X29: =SUM(X260:X271) -> 29924 | Z29: 2024
B30: 2025 | D30: =SUM(D272:D283) -> 32912 | F30: =SUM(F272:F283) -> 1118 | G30: =SUM(G272:G283) -> 0 | H30: =SUM(H272:H283) -> 362 | J30: =SUM(J272:J283) -> 80 | L30: =SUM(L272:L283) -> 311 | N30: =SUM(N272:N283) -> 1398 | P30: =SUM(P272:P283) -> 384 | R30: =SUM(R272:R283) -> 188 | T30: =SUM(T272:T283) -> 225 | U30: =SUM(U272:U283) -> 0 | V30: =SUM(V272:V283) -> 0 | X30: =SUM(X272:X283) -> 36978 | Z30: 2025
B32: 2005 | C32: Jan | D32: 741 | F32: 257 | H32: 244 | J32: 25 | L32: 96 | N32: 19 | P32: 51 | R32: 48 | T32: 24 | U32: - | X32: =SUM(D32:U32) -> 1505 | Z32: 2005 | AA32: Jan
B33: 2005 | C33: Feb | D33: 452 | F33: 179 | H33: 138 | J33: 11 | L33: 59 | N33: 12 | P33: 22 | R33: 14 | T33: 16 | U33: - | X33: =SUM(D33:U33) -> 903 | Z33: 2005 | AA33: Fév
B34: 2005 | C34: Mar | D34: 541 | F34: 235 | H34: 87 | J34: 20 | L34: 67 | N34: 33 | P34: 36 | R34: 22 | T34: 14 | U34: 3 | X34: =SUM(D34:U34) -> 1058 | Z34: 2005 | AA34: Mar
B35: 2005 | C35: Apr | D35: 566 | F35: 283 | H35: 100 | J35: 16 | L35: 83 | N35: 37 | P35: 60 | R35: 25 | T35: 16 | U35: - | X35: =SUM(D35:U35) -> 1186 | Z35: 2005 | AA35: Avr
B36: 2005 | C36: May | D36: 446 | F36: 149 | H36: 123 | J36: 17 | L36: 52 | N36: 26 | P36: 21 | R36: 12 | T36: 14 | U36: - | X36: =SUM(D36:U36) -> 860 | Z36: 2005 | AA36: Mai
B37: 2005 | C37: Jun | D37: 945 | F37: 63 | H37: 10 | J37: 5 | L37: 16 | N37: 16 | P37: 16 | R37: 38 | T37: 2 | U37: - | X37: =SUM(D37:U37) -> 1111 | Z37: 2005 | AA37: Juin
B38: 2005 | C38: July | D38: 563 | F38: 266 | H38: 137 | J38: 25 | L38: 79 | N38: 52 | P38: 144 | R38: 23 | T38: 18 | U38: - | X38: =SUM(D38:U38) -> 1307 | Z38: 2005 | AA38: Juil
B39: 2005 | C39: Aug | D39: 560 | F39: 302 | H39: 110 | J39: 18 | L39: 56 | N39: 45 | P39: 27 | R39: 21 | T39: 29 | U39: - | X39: =SUM(D39:U39) -> 1168 | Z39: 2005 | AA39: Aoû
B40: 2005 | C40: Sep | D40: 466 | F40: 222 | H40: 132 | J40: 19 | L40: 73 | N40: 32 | P40: 47 | R40: 19 | T40: 22 | U40: - | X40: =SUM(D40:U40) -> 1032 | Z40: 2005 | AA40: Sep
B41: 2005 | C41: Oct | D41: 530 | F41: 236 | H41: 81 | J41: 23 | L41: 68 | N41: 16 | P41: 22 | R41: 47 | T41: 14 | U41: - | X41: =SUM(D41:U41) -> 1037 | Z41: 2005 | AA41: Oct
B42: 2005 | C42: Nov | D42: 776 | F42: 200 | H42: 84 | J42: 19 | L42: 57 | N42: 14 | P42: 16 | R42: 15 | T42: 13 | U42: 1 | X42: =SUM(D42:U42) -> 1195 | Z42: 2005 | AA42: Nov
B43: 2005 | C43: Dec | D43: 1002 | F43: 183 | H43: 128 | J43: 17 | L43: 49 | N43: 20 | P43: 24 | R43: 20 | T43: 10 | U43: - | X43: =SUM(D43:U43) -> 1453 | Z43: 2005 | AA43: Déc
B44: 2006 | C44: Jan | D44: 673 | F44: 347 | H44: 146 | J44: 26 | L44: 118 | N44: 26 | P44: 75 | R44: 61 | T44: 24 | U44: - | X44: =SUM(D44:U44) -> 1496 | Z44: 2006 | AA44: Jan
...

Sheet Visitors LOS2wrkingOut
C2: Table 5 : Visitors Arrival Intended Length of Stay
C3: Tableau 5 : Arrivée des Visiteurs à longue durée de Séjour
C5: Year | D5: Month | E5: AVERAGE INTENDED LENGTH OF STAY (LOS) | H5: RATING | J5: Année | K5: Mois
E6: Port Vila | F6: Luganville | G6: Total Average Days | H6: LOS | I6: Main purpose of stay
C7: 2009 | D7: Jan | E7: 0 | F7: 0 | G7: =(E7+F7)/2 -> 0 | J7: 2009 | K7: Jan
D8: Feb | E8: 0 | F8: 0 | G8: =(E8+F8)/2 -> 0 | K8: Fév
D9: Mar | E9: 0 | F9: 0 | G9: =(E9+F9)/2 -> 0 | K9: Mar
D10: Apr | E10: 0 | F10: 0 | G10: =(E10+F10)/2 -> 0 | K10: Avr
D11: May | E11: 0 | F11: 0 | G11: =(E11+F11)/2 -> 0 | K11: Mai
D12: Jun | E12: =#REF! -> #REF! | F12: 0 | G12: =(E12+F12)/2 -> #REF! | H12: =REPT("|",G12) -> #REF! | I12: =IF(G12<4,"Transit",IF(G12<7,"Holiday",IF(G12<10.5,"Holiday/Business",IF(G12<15,"Visiting friends and families")))) -> #REF! | J12: 2009 | K12: Juin
D13: Jul | E13: =#REF! -> #REF! | F13: =#REF! -> #REF! | G13: =(E13+F13)/2 -> #REF! | H13: =REPT("|",G13) -> #REF! | I13: =IF(G13<4,"Transit",IF(G13<7,"Holiday",IF(G13<10.5,"Holiday/Business",IF(G13<15,"Visiting friends and families")))) -> #REF! | K13: Juil
D14: Aug | E14: =#REF! -> #REF! | F14: =#REF! -> #REF! | G14: =(E14+F14)/2 -> #REF! | H14: =REPT("|",G14) -> #REF! | I14: =IF(G14<4,"Transit",IF(G14<7,"Holiday",IF(G14<10.5,"Holiday/Business",IF(G14<15,"Visiting friends and families")))) -> #REF! | K14: Aoû
D15: Sep | E15: =#REF! -> #REF! | F15: =#REF! -> #REF! | G15: =(E15+F15)/2 -> #REF! | H15: =REPT("|",G15) -> #REF! | I15: =IF(G15<4,"Transit",IF(G15<7,"Holiday",IF(G15<10.5,"Holiday/Business",IF(G15<15,"Visiting friends and families")))) -> #REF! | K15: Sep
C16: 2009 | D16: Oct | E16: =#REF! -> #REF! | F16: =#REF! -> #REF! | G16: =(E16+F16)/2 -> #REF! | H16: =REPT("|",G16) -> #REF! | I16: =IF(G16<4,"Transit",IF(G16<5,"Holiday",IF(G16<8.7,"Business/Holiday",IF(G16<10,"Business",IF(G16<14,"Visiting friends/families"))))) -> #REF! | J16: 2009 | K16: Oct
C18: 2009 | D18: Nov | E18: =#REF! -> #REF! | F18: =#REF! -> #REF! | G18: =(E18+F18)/2 -> #REF! | H18: =REPT("|",G18) -> #REF! | I18: =IF(G18<4,"Transit",IF(G18<5.1,"Holiday",IF(G18<9.1,"Business/Holiday",IF(G18<10.6,"Business",IF(G18>10.6,"Visiting friends/families"))))) -> #REF! | J18: 2009 | K18: Nov
D19: Dec | E19: =#REF! -> #REF! | F19: =#REF! -> #REF! | G19: =(E19+F19)/2 -> #REF! | H19: =REPT("|",G19) -> #REF! | I19: =IF(G19<4,"Transit",IF(G19<5.1,"Holiday",IF(G19<9.1,"Business/Holiday",IF(G19<10.6,"Business",IF(G19>10.6,"Visiting friends/families"))))) -> #REF! | K19: Dec
C20: 2010 | D20: Jan | E20: =#REF! -> #REF! | F20: =#REF! -> #REF! | G20: =(E20+F20)/2 -> #REF! | H20: =REPT("|",G20) -> #REF! | I20: =IF(G20<4,"Transit",IF(G20<5.1,"Holiday",IF(G20<9.1,"Business/Holiday",IF(G20<10.6,"Business",IF(G20>10.6,"Visiting friends/families"))))) -> #REF! | J20: 2010 | K20: Jan
D21: Feb | E21: =#REF! -> #REF! | F21: =#REF! -> #REF! | G21: =(E21+F21)/2 -> #REF! | H21: =REPT("|",G21) -> #REF! | I21: =IF(G21<4,"Transit",IF(G21<5.1,"Holiday",IF(G21<9.1,"Business/Holiday",IF(G21<10.6,"Business",IF(G21>10.6,"Visiting friends/families"))))) -> #REF! | K21: Fév
D22: Mar | E22: =#REF! -> #REF! | F22: =#REF! -> #REF! | G22: =(E22+F22)/2 -> #REF! | H22: =REPT("|",G22) -> #REF! | I22: =IF(G22<4,"Transit",IF(G22<5.1,"Holiday",IF(G22<9.1,"Business/Holiday",IF(G22<10.6,"Business",IF(G22>10.6,"Visiting friends/families"))))) -> #REF! | K22: Mar
D23: Apr | E23: =#REF! -> #REF! | F23: =#REF! -> #REF! | G23: =(E23+F23)/2 -> #REF! | H23: =REPT("|",G23) -> #REF! | I23: =IF(G23<4,"Transit",IF(G23<5.1,"Holiday",IF(G23<9.1,"Business/Holiday",IF(G23<10.6,"Business",IF(G23>10.6,"Visiting friends/families"))))) -> #REF! | K23: Avr
D24: May | E24: =#REF! -> #REF! | F24: =#REF! -> #REF! | G24: =(E24+F24)/2 -> #REF! | H24: =REPT("|",G24) -> #REF! | I24: =IF(G24<4,"Transit",IF(G24<5.1,"Holiday",IF(G24<9.1,"Business/Holiday",IF(G24<10.6,"Business",IF(G24>10.6,"Visiting friends/families"))))) -> #REF! | K24: Mai
D25: Jun | E25: =#REF! -> #REF! | F25: =#REF! -> #REF! | G25: =(E25+F25)/2 -> #REF! | H25: =REPT("|",G25) -> #REF! | I25: =IF(G25<4,"Transit",IF(G25<5.1,"Holiday",IF(G25<9.1,"Business/Holiday",IF(G25<10.6,"Business",IF(G25>10.6,"Visiting friends/families"))))) -> #REF! | J25: 2010 | K25: Juin
D26: Jul | E26: =#REF! -> #REF! | F26: =#REF! -> #REF! | G26: =(E26+F26)/2 -> #REF! | H26: =REPT("|",G26) -> #REF! | I26: =IF(G26<4,"Transit",IF(G26<5.1,"Holiday",IF(G26<9.1,"Business/Holiday",IF(G26<10.6,"Business",IF(G26>10.6,"Visiting friends/families"))))) -> #REF! | K26: Juil
D27: Aug | E27: =#REF! -> #REF! | F27: =#REF! -> #REF! | G27: =(E27+F27)/2 -> #REF! | H27: =REPT("|",G27) -> #REF! | I27: =IF(G27<4,"Transit",IF(G27<5.1,"Holiday",IF(G27<9.1,"Business/Holiday",IF(G27<10.6,"Business",IF(G27>10.6,"Visiting friends/families"))))) -> #REF! | K27: Aoû
D28: Sep | E28: =#REF! -> #REF! | F28: =#REF! -> #REF! | G28: =(E28+F28)/2 -> #REF! | H28: =REPT("|",G28) -> #REF! | I28: =IF(G28<4,"Transit",IF(G28<5.1,"Holiday",IF(G28<9.1,"Business/Holiday",IF(G28<10.6,"Business",IF(G28>10.6,"Visiting friends/families"))))) -> #REF! | K28: Sep
C29: 2010 | D29: Oct | E29: =#REF! -> #REF! | F29: =#REF! -> #REF! | G29: =(E29+F29)/2 -> #REF! | H29: =REPT("|",G29) -> #REF! | I29: =IF(G29<4,"Transit",IF(G29<5.1,"Holiday",IF(G29<9.1,"Business/Holiday",IF(G29<10.6,"Business",IF(G29>10.6,"Visiting friends/families"))))) -> #REF! | J29: 2010 | K29: Oct
C30: 2010 | D30: Nov | E30: =#REF! -> #REF! | F30: =#REF! -> #REF! | G30: =(E30+F30)/2 -> #REF! | H30: =REPT("|",G30) -> #REF! | I30: =IF(G30<4,"Transit",IF(G30<5.1,"Holiday",IF(G30<9.1,"Business/Holiday",IF(G30<10.6,"Business",IF(G30>10.6,"Visiting friends/families"))))) -> #REF! | J30: 2010 | K30: Nov
D31: Dec | E31: =#REF! -> #REF! | F31: =#REF! -> #REF! | G31: =(E31+F31)/2 -> #REF! | H31: =REPT("|",G31) -> #REF! | I31: =IF(G31<4,"Transit",IF(G31<5.1,"Holiday",IF(G31<9.1,"Business/Holiday",IF(G31<10.6,"Business",IF(G31>10.6,"Visiting friends/families"))))) -> #REF! | K31: Dec
C32: 2011 | D32: Jan | E32: 8.6380049 | F32: 9.3602941 | G32: =(E32+F32)/2 -> 8.9991495 | H32: =REPT("|",G32) -> |||||||| | I32: =IF(G32<4,"Transit",IF(G32<5.1,"Holiday",IF(G32<9.1,"Business/Holiday",IF(G32<10.6,"Business",IF(G32>10.6,"Visiting friends/families"))))) -> Business/Holiday | J32: 2011 | K32: Jan
D33: Feb | E33: 8.3964082 | F33: 11.448276 | G33: =(E33+F33)/2 -> 9.922342 | H33: =REPT("|",G33) -> ||||||||| | I33: =IF(G33<4,"Transit",IF(G33<5.1,"Holiday",IF(G33<9.1,"Business/Holiday",IF(G33<10.6,"Business",IF(G33>10.6,"Visiting friends/families"))))) -> Business | K33: Fév
D34: Mar | E34: 8.7973648 | F34: 8.344086 | G34: =(E34+F34)/2 -> 8.5707254 | H34: =REPT("|",G34) -> |||||||| | I34: =IF(G34<4,"Transit",IF(G34<5.1,"Holiday",IF(G34<9.1,"Business/Holiday",IF(G34<10.6,"Business",IF(G34>10.6,"Visiting friends/families"))))) -> Business/Holiday | K34: Mar
D35: Apr | E35: 8.2138628 | F35: 13.838983 | G35: =(E35+F35)/2 -> 11.026423 | H35: =REPT("|",G35) -> ||||||||||| | I35: =IF(G35<4,"Transit",IF(G35<5.1,"Holiday",IF(G35<9.1,"Business/Holiday",IF(G35<10.6,"Business",IF(G35>10.6,"Visiting friends/families"))))) -> Visiting friends/families | K35: Apr
D36: May | E36: 9.1427656 | F36: 10.446701 | G36: =(E36+F36)/2 -> 9.794733 | H36: =REPT("|",G36) -> ||||||||| | I36: =IF(G36<4,"Transit",IF(G36<5.1,"Holiday",IF(G36<9.1,"Business/Holiday",IF(G36<10.6,"Business",IF(G36>10.6,"Visiting friends/families"))))) -> Business | K36: Mai
D37: Jun | E37: 8.589365 | F37: 12.584906 | G37: =(E37+F37)/2 -> 10.587135 | H37: =REPT("|",G37) -> |||||||||| | I37: =IF(G37<4,"Transit",IF(G37<5.1,"Holiday",IF(G37<9.1,"Business/Holiday",IF(G37<10.6,"Business",IF(G37>10.6,"Visiting friends/families"))))) -> Business | K37: Juin
D38: Jul | E38: 8.9597811 | F38: 10.425806 | G38: =(E38+F38)/2 -> 9.6927938 | H38: =REPT("|",G38) -> ||||||||| | I38: =IF(G38<4,"Transit",IF(G38<5.1,"Holiday",IF(G38<9.1,"Business/Holiday",IF(G38<10.6,"Business",IF(G38>10.6,"Visiting friends/families"))))) -> Business | K38: Juil
D39: Aug | E39: 8.9640039 | F39: 10.828338 | G39: =(E39+F39)/2 -> 9.8961709 | H39: =REPT("|",G39) -> ||||||||| | I39: =IF(G39<4,"Transit",IF(G39<5.1,"Holiday",IF(G39<9.1,"Business/Holiday",IF(G39<10.6,"Business",IF(G39>10.6,"Visiting friends/families"))))) -> Business | K39: Aoû
